Workbook
Name MileageRate: 'Settings'!$B$4
Name MarketRankingMinimumVisits: 'Settings'!$B$5
Name TestingMode: 'Settings'!$B$7
Name WeeklyProfitGoal: 'Settings'!$B$8
Name CurrentWeekStart: =TODAY()-WEEKDAY(TODAY(),2)+1
Name CurrentWeekEnd: =CurrentWeekStart+6
Name CurrentMonthStart: =EOMONTH(TODAY(),-1)+1
Name CurrentYearStart: =DATE(YEAR(TODAY()),1,1)
Name MissingImportCount: 'Operations_Dashboard'!$B$5
Name ProductsRequiringAction: 'Operations_Dashboard'!$E$5
Name InventoryIssueCount: 'Operations_Dashboard'!$H$5
Name MarketMasterIssueCount: 'Operations_Dashboard'!$K$4
Name fxWorkbookHealth: 'Operations_Dashboard'!$B$4
Name fxWeeklyRevenue: 'Business_Dashboard'!$B$4
Name fxWeeklyProfit: 'Business_Dashboard'!$B$10
Name WorkbookVersion: 'Workbook_Version'!$A$4

Sheet Testing_Dashboard
A1: Enterprise Testing Dashboard
A3: Total Tests | B3: =ROWS(tblRegressionTests[Test ID]) | D3: Category | E3: Total | F3: Passed | G3: Failed
A4: Passed | B4: =COUNTIF(tblRegressionTests[Status],"PASS") | D4: Dashboard | E4: =COUNTIF(tblRegressionTests[Category],D4) | F4: =COUNTIFS(tblRegressionTests[Category],D4,tblRegressionTests[Status],"PASS") | G4: =COUNTIFS(tblRegressionTests[Category],D4,tblRegressionTests[Status],"FAIL")
A5: Failed | B5: =COUNTIF(tblRegressionTests[Status],"FAIL") | D5: Inventory | E5: =COUNTIF(tblRegressionTests[Category],D5) | F5: =COUNTIFS(tblRegressionTests[Category],D5,tblRegressionTests[Status],"PASS") | G5: =COUNTIFS(tblRegressionTests[Category],D5,tblRegressionTests[Status],"FAIL")
A6: Pass Rate | B6: =IFERROR(B4/B3,0) | D6: Product | E6: =COUNTIF(tblRegressionTests[Category],D6) | F6: =COUNTIFS(tblRegressionTests[Category],D6,tblRegressionTests[Status],"PASS") | G6: =COUNTIFS(tblRegressionTests[Category],D6,tblRegressionTests[Status],"FAIL")
A7: Release Gate | B7: =IF(B5=0,"READY","BLOCKED") | D7: Market | E7: =COUNTIF(tblRegressionTests[Category],D7) | F7: =COUNTIFS(tblRegressionTests[Category],D7,tblRegressionTests[Status],"PASS") | G7: =COUNTIFS(tblRegressionTests[Category],D7,tblRegressionTests[Status],"FAIL")
D8: Governance | E8: =COUNTIF(tblRegressionTests[Category],D8) | F8: =COUNTIFS(tblRegressionTests[Category],D8,tblRegressionTests[Status],"PASS") | G8: =COUNTIFS(tblRegressionTests[Category],D8,tblRegressionTests[Status],"FAIL")

Sheet START_HERE
A1: START HERE
A3: Golden Rule
A4: Weekly use should require only: (1) place Square export files, (2) Refresh All, (3) complete Weekly Entry, and review dashboards.
A6: Step | B6: Action
A7: 1 | B7: Place Square export file(s) in the approved folder.
A8: 2 | B8: Data > Refresh All.
A9: 3 | B9: Complete Weekly_Entry: markets, production exceptions, purchases, expenses.
A10: 4 | B10: Review Operations_Dashboard, then Business_Dashboard.
A11: 5 | B11: Run TESTING before increasing the workbook version.
A14: Product ID warning
A15: Use Square Variation ID as the product key. Confirm the Square export contains Variation ID. If not, import a catalog export and map by SKU or Item + Variation name. Do not permanently match by product name alone.
A18: Refresh sequence
A19: Order | B19: Refresh Step
A20: 1 | B20: Import Square files
A21: 2 | B21: Refresh staging queries
A22: 3 | B22: Refresh Product Master
A23: 4 | B23: Refresh Inventory and rankings
A24: 5 | B24: Refresh dashboards
A25: 6 | B25: Run TESTING
A28: Market Master governance
A29: Never edit a historical market-default row. End-date it and add a new row. Market Master defines cost/mileage defaults only and does not imply attendance.
A32: v3.0 Additions
A33: Executive dashboard, Monthly/YTD KPIs, reorder engine, inventory valuation, forecasting, product scorecards, market opportunity scoring, data quality dashboard, release certification, and Power Query stubs.
A36: Regression Testing
A37: Use Regression_Summary for the release gate and Regression_Tests for detailed diagnostics. The suite contains 110 automated tests across dashboards, inventory, products, markets, and governance.

Sheet Weekly_Entry
A1: WEEKLY ENTRY
A3: Markets
A4: Test Key | B4: Market Date | C4: Market | D4: Market Status | E4: Market Day Score | F4: Notes | G4: Override Miles | H4: Attendance Category | I4: Market Match Count | J4: Market Fee | K4: Actual Miles | L4: Travel Cost | M4: Imported Sales Rows | N4: Import Status | O4: Test Record
A5: TEST-MKT-01 | B5: 46027 | C5: TEST-ORLANDO | D5: Attended | E5: Good | F5: Fixture | H5: =IF(OR(tblWeeklyMarkets[[#This Row],[Market Status]]="Attended",tblWeeklyMarkets[[#This Row],[Market Status]]="Partial Day"),"Attended",IF(OR(tblWeeklyMarkets[[#This Row],[Market Status]]="Vacation",tblWeeklyMarkets[[#This Row],[Market Status]]="Family",tblWeeklyMarkets[[#This Row],[Market Status]]="Personal",tblWeeklyMarkets[[#This Row],[Market Status]]="Illness",tblWeeklyMarkets[[#This Row],[Market Status]]="Emergency"),"Excluded","Not Attended")) | I5: =SUMPRODUCT(--(tblMarketMaster[Market]=tblWeeklyMarkets[[#This Row],[Market]]),--(tblMarketMaster[Start Date]<=tblWeeklyMarkets[[#This Row],[Market Date]]),--(IF(tblMarketMaster[End Date]="",DATE(9999,12,31),tblMarketMaster[End Date])>=tblWeeklyMarkets[[#This Row],[Market Date]])) | J5: =IF(tblWeeklyMarkets[[#This Row],[Attendance Category]]<>"Attended",0,IF(tblWeeklyMarkets[[#This Row],[Market Match Count]]<>1,"",_xlfn.XLOOKUP(1,(tblMarketMaster[Market]=tblWeeklyMarkets[[#This Row],[Market]])*(tblMarketMaster[Start Date]<=tblWeeklyMarkets[[#This Row],[Market Date]])*(IF(tblMarketMaster[End Date]="",DATE(9999,12,31),tblMarketMaster[End Date])>=tblWeeklyMarkets[[#This Row],[Market Date]]),tblMarketMaster[Market Fee],""))) | K5: =IF(tblWeeklyMarkets[[#This Row],[Attendance Category]]<>"Attended",0,IF(tblWeeklyMarkets[[#This Row],[Override Miles]]<>"",tblWeeklyMarkets[[#This Row],[Override Miles]],IF(tblWeeklyMarkets[[#This Row],[Market Match Count]]<>1,"",_xlfn.XLOOKUP(1,(tblMarketMaster[Market]=tblWeeklyMarkets[[#This Row],[Market]])*(tblMarketMaster[Start Date]<=tblWeeklyMarkets[[#This Row],[Market Date]])*(IF(tblMarketMaster[End Date]="",DATE(9999,12,31),tblMarketMaster[End Date])>=tblWeeklyMarkets[[#This Row],[Market Date]]),tblMarketMaster[Default Round Trip Miles],"")))) | L5: =IFERROR(tblWeeklyMarkets[[#This Row],[Actual Miles]]*MileageRate,0) | M5: =COUNTIFS(tblSalesData[Sale Timestamp],">="&tblWeeklyMarkets[[#This Row],[Market Date]],tblSalesData[Sale Timestamp],"<"&(tblWeeklyMarkets[[#This Row],[Market Date]]+1),tblSalesData[Test Record],tblWeeklyMarkets[[#This Row],[Test Record]]) | N5: =IF(tblWeeklyMarkets[[#This Row],[Attendance Category]]="Excluded","EXCLUDED",IF(tblWeeklyMarkets[[#This Row],[Attendance Category]]<>"Attended","NOT EXPECTED",IF(tblWeeklyMarkets[[#This Row],[Imported Sales Rows]]>0,"IMPORTED","SALES DATA NOT IMPORTED"))) | O5: Yes
A6: TEST-MKT-02 | B6: 46034 | C6: TEST-ORLANDO | D6: Vacation | E6: Average | F6: Fixture | H6: =IF(OR(tblWeeklyMarkets[[#This Row],[Market Status]]="Attended",tblWeeklyMarkets[[#This Row],[Market Status]]="Partial Day"),"Attended",IF(OR(tblWeeklyMarkets[[#This Row],[Market Status]]="Vacation",tblWeeklyMarkets[[#This Row],[Market Status]]="Family",tblWeeklyMarkets[[#This Row],[Market Status]]="Personal",tblWeeklyMarkets[[#This Row],[Market Status]]="Illness",tblWeeklyMarkets[[#This Row],[Market Status]]="Emergency"),"Excluded","Not Attended")) | I6: =SUMPRODUCT(--(tblMarketMaster[Market]=tblWeeklyMarkets[[#This Row],[Market]]),--(tblMarketMaster[Start Date]<=tblWeeklyMarkets[[#This Row],[Market Date]]),--(IF(tblMarketMaster[End Date]="",DATE(9999,12,31),tblMarketMaster[End Date])>=tblWeeklyMarkets[[#This Row],[Market Date]])) | J6: =IF(tblWeeklyMarkets[[#This Row],[Attendance Category]]<>"Attended",0,IF(tblWeeklyMarkets[[#This Row],[Market Match Count]]<>1,"",_xlfn.XLOOKUP(1,(tblMarketMaster[Market]=tblWeeklyMarkets[[#This Row],[Market]])*(tblMarketMaster[Start Date]<=tblWeeklyMarkets[[#This Row],[Market Date]])*(IF(tblMarketMaster[End Date]="",DATE(9999,12,31),tblMarketMaster[End Date])>=tblWeeklyMarkets[[#This Row],[Market Date]]),tblMarketMaster[Market Fee],""))) | K6: =IF(tblWeeklyMarkets[[#This Row],[Attendance Category]]<>"Attended",0,IF(tblWeeklyMarkets[[#This Row],[Override Miles]]<>"",tblWeeklyMarkets[[#This Row],[Override Miles]],IF(tblWeeklyMarkets[[#This Row],[Market Match Count]]<>1,"",_xlfn.XLOOKUP(1,(tblMarketMaster[Market]=tblWeeklyMarkets[[#This Row],[Market]])*(tblMarketMaster[Start Date]<=tblWeeklyMarkets[[#This Row],[Market Date]])*(IF(tblMarketMaster[End Date]="",DATE(9999,12,31),tblMarketMaster[End Date])>=tblWeeklyMarkets[[#This Row],[Market Date]]),tblMarketMaster[Default Round Trip Miles],"")))) | L6: =IFERROR(tblWeeklyMarkets[[#This Row],[Actual Miles]]*MileageRate,0) | M6: =COUNTIFS(tblSalesData[Sale Timestamp],">="&tblWeeklyMarkets[[#This Row],[Market Date]],tblSalesData[Sale Timestamp],"<"&(tblWeeklyMarkets[[#This Row],[Market Date]]+1),tblSalesData[Test Record],tblWeeklyMarkets[[#This Row],[Test Record]]) | N6: =IF(tblWeeklyMarkets[[#This Row],[Attendance Category]]="Excluded","EXCLUDED",IF(tblWeeklyMarkets[[#This Row],[Attendance Category]]<>"Attended","NOT EXPECTED",IF(tblWeeklyMarkets[[#This Row],[Imported Sales Rows]]>0,"IMPORTED","SALES DATA NOT IMPORTED"))) | O6: Yes
A10: Production Exceptions
A11: Week Start | B11: Variation ID | C11: Product Name | D11: Quantity Made | E11: Samples Given | F11: Notes | G11: Test Record
A12: 46027 | B12: TEST-VAR001 | C12: Test Jam 8 oz | D12: 20 | E12: 2 | F12: Fixture | G12: Yes
A16: Purchase Date | B16: Purchase Type | C16: Store | D16: Receipt ID | E16: Ingredient | F16: Quantity | G16: Unit | H16: Total Cost | I16: Notes | J16: Validation | K16: Test Record
A17: 46027 | B17: Item | C17: Test Store | D17: R-TEST-1 | E17: Sugar | F17: 25 | G17: lb | H17: 18 | I17: Fixture | J17: =IF(AND(tblIngredientPurchases[[#This Row],[Purchase Type]]="Item",OR(tblIngredientPurchases[[#This Row],[Ingredient]]="",tblIngredientPurchases[[#This Row],[Quantity]]="")),"INCOMPLETE","OK") | K17: Yes
A21: Date | B21: Category | C21: Amount | D21: Description | E21: Test Record
A22: 46027 | B22: Packaging | C22: 12 | D22: Fixture | E22: Yes

Sheet Product_Setup
A1: PRODUCT SETUP
A3: Variation ID | B3: Item ID | C3: Product Name | D3: Variation Name | E3: Shelf Stable | F3: Spoils If Unsold | G3: Product Group | H3: Product Active | I3: Recipe Complete | J3: Cost Complete | K3: Product Status | L3: Missing Items | M3: Effective Product Cost | N3: Test Record
A4: TEST-VAR001 | B4: TEST-ITEM1 | C4: Test Strawberry Jam | D4: 8 oz | E4: Yes | F4: Yes | G4: Jam | H4: Yes | I4: Yes | J4: Yes | K4: READY | M4: 2.15 | N4: Yes
A5: TEST-VAR002 | B5: TEST-ITEM1 | C5: Test Strawberry Jam | D5: 16 oz | E5: Yes | F5: No | G5: Jam | H5: Yes | I5: Yes | J5: No | K5: SETUP REQUIRED | L5: Cost | N5: Yes
A6: TEST-VAR003 | B6: TEST-ITEM2 | C6: Test Fresh Bread | D6: Regular | E6: No | F6: Yes | G6: Fresh | H6: Yes | I6: No | J6: Yes | K6: SETUP REQUIRED | L6: Recipe | M6: 1.5 | N6: Yes
A7: TEST-VAR004 | B7: TEST-ITEM3 | C7: Test Hot Honey | D7: Regular | E7: Yes | F7: Yes | G7: Honey | H7: Yes | I7: No | J7: No | K7: CONFIGURE PRODUCT | L7: Recipe, Cost | N7: Yes

Sheet Operations_Dashboard
A1: OPERATIONS DASHBOARD
A3: Import Health | D3: Product Health | G3: Inventory Health | J3: Market Master Health
A4: Workbook Health | B4: =_xlfn.IFS(B5>0,"SALES DATA NOT IMPORTED",E6>0,"PRODUCT SETUP REQUIRED",K5>0,"MARKET MASTER REVIEW REQUIRED",H6>0,"INVENTORY REVIEW REQUIRED",TRUE,"WORKBOOK HEALTHY") | D4: Products Ready | E4: =COUNTIFS(tblProductMaster[Product Status],"READY",tblProductMaster[Test Record],"No") | G4: Snapshot Date | H4: =IFERROR(_xlfn.MAXIFS(tblInventory[Inventory Date],tblInventory[Test Record],"No"),"") | J4: Configuration Issues | K4: =COUNTIFS(tblMarketMaster[Overlap Count],">0",tblMarketMaster[Test Record],"No")+COUNTIFS(tblMarketMaster[Fee Validation],"<>OK",tblMarketMaster[Test Record],"No")+COUNTIFS(tblMarketMaster[Invalid Date Range],"INVALID",tblMarketMaster[Test Record],"No")
A5: Missing Imports | B5: =COUNTIFS(tblWeeklyMarkets[Import Status],"SALES DATA NOT IMPORTED",tblWeeklyMarkets[Test Record],"No") | D5: Products Requiring Action | E5: =COUNTIFS(tblProductMaster[Product Status],"<>READY",tblProductMaster[Test Record],"No") | G5: Inventory Movement Errors | H5: =COUNTIFS(tblInventory[Validation],"<>OK",tblInventory[Test Record],"No")
A6: Imported Markets | B6: =COUNTIFS(tblWeeklyMarkets[Import Status],"IMPORTED",tblWeeklyMarkets[Test Record],"No") | D6: Missing Recipes | E6: =COUNTIFS(tblProductMaster[Recipe Complete],"No",tblProductMaster[Test Record],"No") | G6: Current Inventory Units | H6: =_xlfn.LET(Dt,IFERROR(_xlfn.MAXIFS(tblInventory[Inventory Date],tblInventory[Test Record],"No"),0),IF(Dt=0,0,SUMIFS(tblInventory[Ending Inventory],tblInventory[Inventory Date],Dt,tblInventory[Test Record],"No")))
A7: Excluded Markets | B7: =COUNTIFS(tblWeeklyMarkets[Import Status],"EXCLUDED",tblWeeklyMarkets[Test Record],"No") | D7: Missing Costs | E7: =COUNTIFS(tblProductMaster[Cost Complete],"No",tblProductMaster[Test Record],"No")
A8: Last Successful Import | B8: =IFERROR(_xlfn.MAXIFS(tblImportLog[Import Timestamp],tblImportLog[Status],"Success",tblImportLog[Test Record],"No"),"")

Sheet Business_Dashboard
A1: BUSINESS DASHBOARD
A3: Weekly Performance | D3: Rankings | G3: Setup / Waste
A4: Weekly Revenue | B4: =SUMIFS(tblSalesData[Gross Sales],tblSalesData[Sale Timestamp],">="&CurrentWeekStart,tblSalesData[Sale Timestamp],"<"&CurrentWeekEnd+1,tblSalesData[Test Record],"No") | D4: Best Product | E4: =IFERROR(_xlfn.XLOOKUP(1,(tblProductRankings[Profit Rank]=1)*(tblProductRankings[Test Record]="No"),tblProductRankings[Product Name]),"No ranked products") | G4: Product Setup Completion | H4: =IFERROR(COUNTIFS(tblProductMaster[Product Status],"READY",tblProductMaster[Test Record],"No")/COUNTIFS(tblProductMaster[Test Record],"No"),0)
A5: Weekly COGS | B5: =SUMIFS(tblSalesData[COGS],tblSalesData[Sale Timestamp],">="&CurrentWeekStart,tblSalesData[Sale Timestamp],"<"&CurrentWeekEnd+1,tblSalesData[Test Record],"No") | D5: Best Business Market | E5: =IFERROR(_xlfn.XLOOKUP(1,(tblMarketRankings[Business Rank]=1)*(tblMarketRankings[Test Record]="No"),tblMarketRankings[Market]),"No ranked markets") | G5: Waste % | H5: =IFERROR(SUMIFS(tblInventory[Spoilage],tblInventory[Test Record],"No")/SUMIFS(tblInventory[Available],tblInventory[Test Record],"No"),0)
A6: Weekly Market Fees | B6: =SUMIFS(tblWeeklyMarkets[Market Fee],tblWeeklyMarkets[Market Date],">="&CurrentWeekStart,tblWeeklyMarkets[Market Date],"<="&CurrentWeekEnd,tblWeeklyMarkets[Attendance Category],"Attended",tblWeeklyMarkets[Test Record],"No") | D6: Best Travel-Adjusted Market | E6: =IFERROR(_xlfn.XLOOKUP(1,(tblMarketRankings[Personal Rank]=1)*(tblMarketRankings[Test Record]="No"),tblMarketRankings[Market]),"No ranked markets") | G6: Inventory As Of | H6: =IFERROR(_xlfn.MAXIFS(tblInventory[Inventory Date],tblInventory[Test Record],"No"),"")
A7: Weekly Travel Cost | B7: =SUMIFS(tblWeeklyMarkets[Travel Cost],tblWeeklyMarkets[Market Date],">="&CurrentWeekStart,tblWeeklyMarkets[Market Date],"<="&CurrentWeekEnd,tblWeeklyMarkets[Attendance Category],"Attended",tblWeeklyMarkets[Test Record],"No") | D7: Ranked Markets | E7: =COUNTIFS(tblMarketRankings[Eligibility],"Eligible",tblMarketRankings[Test Record],"No")
A8: Weekly Square Fees | B8: =SUMIFS(tblSalesData[Square Fee],tblSalesData[Sale Timestamp],">="&CurrentWeekStart,tblSalesData[Sale Timestamp],"<"&CurrentWeekEnd+1,tblSalesData[Test Record],"No") | D8: Not Ranked Markets | E8: =COUNTIFS(tblMarketRankings[Eligibility],"Not Ranked",tblMarketRankings[Test Record],"No")
A9: Weekly Other Expenses | B9: =SUMIFS(tblExpenses[Amount],tblExpenses[Date],">="&CurrentWeekStart,tblExpenses[Date],"<="&CurrentWeekEnd,tblExpenses[Test Record],"No")
A10: Weekly Profit | B10: =B4-B5-B6-B7-B8-B9

Sheet TESTING
A1: TESTING
A3: Test ID | B3: Test Area | C3: Test Key | D3: Test Date | E3: Expected Result | F3: Actual Result | G3: Status | H3: Notes | J3: Release Status | K3: =IF(COUNTIF(tblTesting[Status],"FAIL")=0,"READY FOR PRODUCTION","TEST FAILURES EXIST")
A4: T020 | B4: Mileage | C4: TEST-MKT-01 | E4: 84 | F4: =_xlfn.SWITCH(tblTesting[[#This Row],[Test ID]],"T020",_xlfn.XLOOKUP(tblTesting[[#This Row],[Test Key]],tblWeeklyMarkets[Test Key],tblWeeklyMarkets[Actual Miles],"NOT FOUND"),"T022",_xlfn.XLOOKUP(tblTesting[[#This Row],[Test Key]],tblWeeklyMarkets[Test Key],tblWeeklyMarkets[Travel Cost],"NOT FOUND"),"T030",_xlfn.XLOOKUP(tblTesting[[#This Row],[Test Key]],tblWeeklyMarkets[Test Key],tblWeeklyMarkets[Attendance Category],"NOT FOUND"),"T032",_xlfn.XLOOKUP(tblTesting[[#This Row],[Test Key]],tblWeeklyMarkets[Test Key],tblWeeklyMarkets[Attendance Category],"NOT FOUND"),"T050",_xlfn.XLOOKUP(tblTesting[[#This Row],[Test Key]],tblInventory[Test Key],tblInventory[Spoilage],"NOT FOUND"),"T052",_xlfn.XLOOKUP(tblTesting[[#This Row],[Test Key]],tblInventory[Test Key],tblInventory[Ending Inventory],"NOT FOUND"),"T060",_xlfn.XLOOKUP(tblTesting[[#This Row],[Test Key]],tblIngredientUsage[Test Key],tblIngredientUsage[Quantity Used],"NOT FOUND"),"T080",_xlfn.XLOOKUP(tblTesting[[#This Row],[Test Key]],tblProductMaster[Variation ID],tblProductMaster[Cost Complete],"NOT FOUND"),"T081",_xlfn.XLOOKUP(tblTesting[[#This Row],[Test Key]],tblProductMaster[Variation ID],tblProductMaster[Cost Complete],"NOT FOUND"),"T082",_xlfn.XLOOKUP(tblTesting[[#This Row],[Test Key]],tblProductCosts[Variation ID],tblProductCosts[Cost Review Status],"NOT FOUND"),"TEST NOT DEFINED") | G4: =IF(OR(tblTesting[[#This Row],[Actual Result]]="NOT FOUND",tblTesting[[#This Row],[Actual Result]]="TEST NOT DEFINED"),"FAIL",IF(AND(ISNUMBER(tblTesting[[#This Row],[Expected Result]]),ISNUMBER(tblTesting[[#This Row],[Actual Result]])),IF(ABS(tblTesting[[#This Row],[Expected Result]]-tblTesting[[#This Row],[Actual Result]])<0.01,"PASS","FAIL"),IF(tblTesting[[#This Row],[Expected Result]]=tblTesting[[#This Row],[Actual Result]],"PASS","FAIL"))) | H4: Default mileage | J4: Passed | K4: =COUNTIF(tblTesting[Status],"PASS")
A5: T022 | B5: Travel Cost | C5: TEST-MKT-01 | E5: 56.28 | F5: =_xlfn.SWITCH(tblTesting[[#This Row],[Test ID]],"T020",_xlfn.XLOOKUP(tblTesting[[#This Row],[Test Key]],tblWeeklyMarkets[Test Key],tblWeeklyMarkets[Actual Miles],"NOT FOUND"),"T022",_xlfn.XLOOKUP(tblTesting[[#This Row],[Test Key]],tblWeeklyMarkets[Test Key],tblWeeklyMarkets[Travel Cost],"NOT FOUND"),"T030",_xlfn.XLOOKUP(tblTesting[[#This Row],[Test Key]],tblWeeklyMarkets[Test Key],tblWeeklyMarkets[Attendance Category],"NOT FOUND"),"T032",_xlfn.XLOOKUP(tblTesting[[#This Row],[Test Key]],tblWeeklyMarkets[Test Key],tblWeeklyMarkets[Attendance Category],"NOT FOUND"),"T050",_xlfn.XLOOKUP(tblTesting[[#This Row],[Test Key]],tblInventory[Test Key],tblInventory[Spoilage],"NOT FOUND"),"T052",_xlfn.XLOOKUP(tblTesting[[#This Row],[Test Key]],tblInventory[Test Key],tblInventory[Ending Inventory],"NOT FOUND"),"T060",_xlfn.XLOOKUP(tblTesting[[#This Row],[Test Key]],tblIngredientUsage[Test Key],tblIngredientUsage[Quantity Used],"NOT FOUND"),"T080",_xlfn.XLOOKUP(tblTesting[[#This Row],[Test Key]],tblProductMaster[Variation ID],tblProductMaster[Cost Complete],"NOT FOUND"),"T081",_xlfn.XLOOKUP(tblTesting[[#This Row],[Test Key]],tblProductMaster[Variation ID],tblProductMaster[Cost Complete],"NOT FOUND"),"T082",_xlfn.XLOOKUP(tblTesting[[#This Row],[Test Key]],tblProductCosts[Variation ID],tblProductCosts[Cost Review Status],"NOT FOUND"),"TEST NOT DEFINED") | G5: =IF(OR(tblTesting[[#This Row],[Actual Result]]="NOT FOUND",tblTesting[[#This Row],[Actual Result]]="TEST NOT DEFINED"),"FAIL",IF(AND(ISNUMBER(tblTesting[[#This Row],[Expected Result]]),ISNUMBER(tblTesting[[#This Row],[Actual Result]])),IF(ABS(tblTesting[[#This Row],[Expected Result]]-tblTesting[[#This Row],[Actual Result]])<0.01,"PASS","FAIL"),IF(tblTesting[[#This Row],[Expected Result]]=tblTesting[[#This Row],[Actual Result]],"PASS","FAIL"))) | H5: 84 miles x 0.67 | J5: Failed | K5: =COUNTIF(tblTesting[Status],"FAIL")
A6: T030 | B6: Attendance | C6: TEST-MKT-01 | E6: Attended | F6: =_xlfn.SWITCH(tblTesting[[#This Row],[Test ID]],"T020",_xlfn.XLOOKUP(tblTesting[[#This Row],[Test Key]],tblWeeklyMarkets[Test Key],tblWeeklyMarkets[Actual Miles],"NOT FOUND"),"T022",_xlfn.XLOOKUP(tblTesting[[#This Row],[Test Key]],tblWeeklyMarkets[Test Key],tblWeeklyMarkets[Travel Cost],"NOT FOUND"),"T030",_xlfn.XLOOKUP(tblTesting[[#This Row],[Test Key]],tblWeeklyMarkets[Test Key],tblWeeklyMarkets[Attendance Category],"NOT FOUND"),"T032",_xlfn.XLOOKUP(tblTesting[[#This Row],[Test Key]],tblWeeklyMarkets[Test Key],tblWeeklyMarkets[Attendance Category],"NOT FOUND"),"T050",_xlfn.XLOOKUP(tblTesting[[#This Row],[Test Key]],tblInventory[Test Key],tblInventory[Spoilage],"NOT FOUND"),"T052",_xlfn.XLOOKUP(tblTesting[[#This Row],[Test Key]],tblInventory[Test Key],tblInventory[Ending Inventory],"NOT FOUND"),"T060",_xlfn.XLOOKUP(tblTesting[[#This Row],[Test Key]],tblIngredientUsage[Test Key],tblIngredientUsage[Quantity Used],"NOT FOUND"),"T080",_xlfn.XLOOKUP(tblTesting[[#This Row],[Test Key]],tblProductMaster[Variation ID],tblProductMaster[Cost Complete],"NOT FOUND"),"T081",_xlfn.XLOOKUP(tblTesting[[#This Row],[Test Key]],tblProductMaster[Variation ID],tblProductMaster[Cost Complete],"NOT FOUND"),"T082",_xlfn.XLOOKUP(tblTesting[[#This Row],[Test Key]],tblProductCosts[Variation ID],tblProductCosts[Cost Review Status],"NOT FOUND"),"TEST NOT DEFINED") | G6: =IF(OR(tblTesting[[#This Row],[Actual Result]]="NOT FOUND",tblTesting[[#This Row],[Actual Result]]="TEST NOT DEFINED"),"FAIL",IF(AND(ISNUMBER(tblTesting[[#This Row],[Expected Result]]),ISNUMBER(tblTesting[[#This Row],[Actual Result]])),IF(ABS(tblTesting[[#This Row],[Expected Result]]-tblTesting[[#This Row],[Actual Result]])<0.01,"PASS","FAIL"),IF(tblTesting[[#This Row],[Expected Result]]=tblTesting[[#This Row],[Actual Result]],"PASS","FAIL"))) | H6: Attended category
A7: T032 | B7: Attendance | C7: TEST-MKT-02 | E7: Excluded | F7: =_xlfn.SWITCH(tblTesting[[#This Row],[Test ID]],"T020",_xlfn.XLOOKUP(tblTesting[[#This Row],[Test Key]],tblWeeklyMarkets[Test Key],tblWeeklyMarkets[Actual Miles],"NOT FOUND"),"T022",_xlfn.XLOOKUP(tblTesting[[#This Row],[Test Key]],tblWeeklyMarkets[Test Key],tblWeeklyMarkets[Travel Cost],"NOT FOUND"),"T030",_xlfn.XLOOKUP(tblTesting[[#This Row],[Test Key]],tblWeeklyMarkets[Test Key],tblWeeklyMarkets[Attendance Category],"NOT FOUND"),"T032",_xlfn.XLOOKUP(tblTesting[[#This Row],[Test Key]],tblWeeklyMarkets[Test Key],tblWeeklyMarkets[Attendance Category],"NOT FOUND"),"T050",_xlfn.XLOOKUP(tblTesting[[#This Row],[Test Key]],tblInventory[Test Key],tblInventory[Spoilage],"NOT FOUND"),"T052",_xlfn.XLOOKUP(tblTesting[[#This Row],[Test Key]],tblInventory[Test Key],tblInventory[Ending Inventory],"NOT FOUND"),"T060",_xlfn.XLOOKUP(tblTesting[[#This Row],[Test Key]],tblIngredientUsage[Test Key],tblIngredientUsage[Quantity Used],"NOT FOUND"),"T080",_xlfn.XLOOKUP(tblTesting[[#This Row],[Test Key]],tblProductMaster[Variation ID],tblProductMaster[Cost Complete],"NOT FOUND"),"T081",_xlfn.XLOOKUP(tblTesting[[#This Row],[Test Key]],tblProductMaster[Variation ID],tblProductMaster[Cost Complete],"NOT FOUND"),"T082",_xlfn.XLOOKUP(tblTesting[[#This Row],[Test Key]],tblProductCosts[Variation ID],tblProductCosts[Cost Review Status],"NOT FOUND"),"TEST NOT DEFINED") | G7: =IF(OR(tblTesting[[#This Row],[Actual Result]]="NOT FOUND",tblTesting[[#This Row],[Actual Result]]="TEST NOT DEFINED"),"FAIL",IF(AND(ISNUMBER(tblTesting[[#This Row],[Expected Result]]),ISNUMBER(tblTesting[[#This Row],[Actual Result]])),IF(ABS(tblTesting[[#This Row],[Expected Result]]-tblTesting[[#This Row],[Actual Result]])<0.01,"PASS","FAIL"),IF(tblTesting[[#This Row],[Expected Result]]=tblTesting[[#This Row],[Actual Result]],"PASS","FAIL"))) | H7: Vacation category
A8: T050 | B8: Inventory | C8: TEST-INV-SPOIL | E8: 3 | F8: =_xlfn.SWITCH(tblTesting[[#This Row],[Test ID]],"T020",_xlfn.XLOOKUP(tblTesting[[#This Row],[Test Key]],tblWeeklyMarkets[Test Key],tblWeeklyMarkets[Actual Miles],"NOT FOUND"),"T022",_xlfn.XLOOKUP(tblTesting[[#This Row],[Test Key]],tblWeeklyMarkets[Test Key],tblWeeklyMarkets[Travel Cost],"NOT FOUND"),"T030",_xlfn.XLOOKUP(tblTesting[[#This Row],[Test Key]],tblWeeklyMarkets[Test Key],tblWeeklyMarkets[Attendance Category],"NOT FOUND"),"T032",_xlfn.XLOOKUP(tblTesting[[#This Row],[Test Key]],tblWeeklyMarkets[Test Key],tblWeeklyMarkets[Attendance Category],"NOT FOUND"),"T050",_xlfn.XLOOKUP(tblTesting[[#This Row],[Test Key]],tblInventory[Test Key],tblInventory[Spoilage],"NOT FOUND"),"T052",_xlfn.XLOOKUP(tblTesting[[#This Row],[Test Key]],tblInventory[Test Key],tblInventory[Ending Inventory],"NOT FOUND"),"T060",_xlfn.XLOOKUP(tblTesting[[#This Row],[Test Key]],tblIngredientUsage[Test Key],tblIngredientUsage[Quantity Used],"NOT FOUND"),"T080",_xlfn.XLOOKUP(tblTesting[[#This Row],[Test Key]],tblProductMaster[Variation ID],tblProductMaster[Cost Complete],"NOT FOUND"),"T081",_xlfn.XLOOKUP(tblTesting[[#This Row],[Test Key]],tblProductMaster[Variation ID],tblProductMaster[Cost Complete],"NOT FOUND"),"T082",_xlfn.XLOOKUP(tblTesting[[#This Row],[Test Key]],tblProductCosts[Variation ID],tblProductCosts[Cost Review Status],"NOT FOUND"),"TEST NOT DEFINED") | G8: =IF(OR(tblTesting[[#This Row],[Actual Result]]="NOT FOUND",tblTesting[[#This Row],[Actual Result]]="TEST NOT DEFINED"),"FAIL",IF(AND(ISNUMBER(tblTesting[[#This Row],[Expected Result]]),ISNUMBER(tblTesting[[#This Row],[Actual Result]])),IF(ABS(tblTesting[[#This Row],[Expected Result]]-tblTesting[[#This Row],[Actual Result]])<0.01,"PASS","FAIL"),IF(tblTesting[[#This Row],[Expected Result]]=tblTesting[[#This Row],[Actual Result]],"PASS","FAIL"))) | H8: Auto spoilage
A9: T052 | B9: Inventory | C9: TEST-INV-CARRY | E9: 3 | F9: =_xlfn.SWITCH(tblTesting[[#This Row],[Test ID]],"T020",_xlfn.XLOOKUP(tblTesting[[#This Row],[Test Key]],tblWeeklyMarkets[Test Key],tblWeeklyMarkets[Actual Miles],"NOT FOUND"),"T022",_xlfn.XLOOKUP(tblTesting[[#This Row],[Test Key]],tblWeeklyMarkets[Test Key],tblWeeklyMarkets[Travel Cost],"NOT FOUND"),"T030",_xlfn.XLOOKUP(tblTesting[[#This Row],[Test Key]],tblWeeklyMarkets[Test Key],tblWeeklyMarkets[Attendance Category],"NOT FOUND"),"T032",_xlfn.XLOOKUP(tblTesting[[#This Row],[Test Key]],tblWeeklyMarkets[Test Key],tblWeeklyMarkets[Attendance Category],"NOT FOUND"),"T050",_xlfn.XLOOKUP(tblTesting[[#This Row],[Test Key]],tblInventory[Test Key],tblInventory[Spoilage],"NOT FOUND"),"T052",_xlfn.XLOOKUP(tblTesting[[#This Row],[Test Key]],tblInventory[Test Key],tblInventory[Ending Inventory],"NOT FOUND"),"T060",_xlfn.XLOOKUP(tblTesting[[#This Row],[Test Key]],tblIngredientUsage[Test Key],tblIngredientUsage[Quantity Used],"NOT FOUND"),"T080",_xlfn.XLOOKUP(tblTesting[[#This Row],[Test Key]],tblProductMaster[Variation ID],tblProductMaster[Cost Complete],"NOT FOUND"),"T081",_xlfn.XLOOKUP(tblTesting[[#This Row],[Test Key]],tblProductMaster[Variation ID],tblProductMaster[Cost Complete],"NOT FOUND"),"T082",_xlfn.XLOOKUP(tblTesting[[#This Row],[Test Key]],tblProductCosts[Variation ID],tblProductCosts[Cost Review Status],"NOT FOUND"),"TEST NOT DEFINED") | G9: =IF(OR(tblTesting[[#This Row],[Actual Result]]="NOT FOUND",tblTesting[[#This Row],[Actual Result]]="TEST NOT DEFINED"),"FAIL",IF(AND(ISNUMBER(tblTesting[[#This Row],[Expected Result]]),ISNUMBER(tblTesting[[#This Row],[Actual Result]])),IF(ABS(tblTesting[[#This Row],[Expected Result]]-tblTesting[[#This Row],[Actual Result]])<0.01,"PASS","FAIL"),IF(tblTesting[[#This Row],[Expected Result]]=tblTesting[[#This Row],[Actual Result]],"PASS","FAIL"))) | H9: Carry-forward ending inventory
A10: T060 | B10: Ingredient Usage | C10: TEST-USAGE-1 | E10: 8 | F10: =_xlfn.SWITCH(tblTesting[[#This Row],[Test ID]],"T020",_xlfn.XLOOKUP(tblTesting[[#This Row],[Test Key]],tblWeeklyMarkets[Test Key],tblWeeklyMarkets[Actual Miles],"NOT FOUND"),"T022",_xlfn.XLOOKUP(tblTesting[[#This Row],[Test Key]],tblWeeklyMarkets[Test Key],tblWeeklyMarkets[Travel Cost],"NOT FOUND"),"T030",_xlfn.XLOOKUP(tblTesting[[#This Row],[Test Key]],tblWeeklyMarkets[Test Key],tblWeeklyMarkets[Attendance Category],"NOT FOUND"),"T032",_xlfn.XLOOKUP(tblTesting[[#This Row],[Test Key]],tblWeeklyMarkets[Test Key],tblWeeklyMarkets[Attendance Category],"NOT FOUND"),"T050",_xlfn.XLOOKUP(tblTesting[[#This Row],[Test Key]],tblInventory[Test Key],tblInventory[Spoilage],"NOT FOUND"),"T052",_xlfn.XLOOKUP(tblTesting[[#This Row],[Test Key]],tblInventory[Test Key],tblInventory[Ending Inventory],"NOT FOUND"),"T060",_xlfn.XLOOKUP(tblTesting[[#This Row],[Test Key]],tblIngredientUsage[Test Key],tblIngredientUsage[Quantity Used],"NOT FOUND"),"T080",_xlfn.XLOOKUP(tblTesting[[#This Row],[Test Key]],tblProductMaster[Variation ID],tblProductMaster[Cost Complete],"NOT FOUND"),"T081",_xlfn.XLOOKUP(tblTesting[[#This Row],[Test Key]],tblProductMaster[Variation ID],tblProductMaster[Cost Complete],"NOT FOUND"),"T082",_xlfn.XLOOKUP(tblTesting[[#This Row],[Test Key]],tblProductCosts[Variation ID],tblProductCosts[Cost Review Status],"NOT FOUND"),"TEST NOT DEFINED") | G10: =IF(OR(tblTesting[[#This Row],[Actual Result]]="NOT FOUND",tblTesting[[#This Row],[Actual Result]]="TEST NOT DEFINED"),"FAIL",IF(AND(ISNUMBER(tblTesting[[#This Row],[Expected Result]]),ISNUMBER(tblTesting[[#This Row],[Actual Result]])),IF(ABS(tblTesting[[#This Row],[Expected Result]]-tblTesting[[#This Row],[Actual Result]])<0.01,"PASS","FAIL"),IF(tblTesting[[#This Row],[Expected Result]]=tblTesting[[#This Row],[Actual Result]],"PASS","FAIL"))) | H10: 20 x 0.4
A11: T080 | B11: Product Setup | C11: TEST-VAR001 | E11: Yes | F11: =_xlfn.SWITCH(tblTesting[[#This Row],[Test ID]],"T020",_xlfn.XLOOKUP(tblTesting[[#This Row],[Test Key]],tblWeeklyMarkets[Test Key],tblWeeklyMarkets[Actual Miles],"NOT FOUND"),"T022",_xlfn.XLOOKUP(tblTesting[[#This Row],[Test Key]],tblWeeklyMarkets[Test Key],tblWeeklyMarkets[Travel Cost],"NOT FOUND"),"T030",_xlfn.XLOOKUP(tblTesting[[#This Row],[Test Key]],tblWeeklyMarkets[Test Key],tblWeeklyMarkets[Attendance Category],"NOT FOUND"),"T032",_xlfn.XLOOKUP(tblTesting[[#This Row],[Test Key]],tblWeeklyMarkets[Test Key],tblWeeklyMarkets[Attendance Category],"NOT FOUND"),"T050",_xlfn.XLOOKUP(tblTesting[[#This Row],[Test Key]],tblInventory[Test Key],tblInventory[Spoilage],"NOT FOUND"),"T052",_xlfn.XLOOKUP(tblTesting[[#This Row],[Test Key]],tblInventory[Test Key],tblInventory[Ending Inventory],"NOT FOUND"),"T060",_xlfn.XLOOKUP(tblTesting[[#This Row],[Test Key]],tblIngredientUsage[Test Key],tblIngredientUsage[Quantity Used],"NOT FOUND"),"T080",_xlfn.XLOOKUP(tblTesting[[#This Row],[Test Key]],tblProductMaster[Variation ID],tblProductMaster[Cost Complete],"NOT FOUND"),"T081",_xlfn.XLOOKUP(tblTesting[[#This Row],[Test Key]],tblProductMaster[Variation ID],tblProductMaster[Cost Complete],"NOT FOUND"),"T082",_xlfn.XLOOKUP(tblTesting[[#This Row],[Test Key]],tblProductCosts[Variation ID],tblProductCosts[Cost Review Status],"NOT FOUND"),"TEST NOT DEFINED") | G11: =IF(OR(tblTesting[[#This Row],[Actual Result]]="NOT FOUND",tblTesting[[#This Row],[Actual Result]]="TEST NOT DEFINED"),"FAIL",IF(AND(ISNUMBER(tblTesting[[#This Row],[Expected Result]]),ISNUMBER(tblTesting[[#This Row],[Actual Result]])),IF(ABS(tblTesting[[#This Row],[Expected Result]]-tblTesting[[#This Row],[Actual Result]])<0.01,"PASS","FAIL"),IF(tblTesting[[#This Row],[Expected Result]]=tblTesting[[#This Row],[Actual Result]],"PASS","FAIL"))) | H11: Cost complete
A12: T081 | B12: Product Setup | C12: TEST-VAR002 | E12: No | F12: =_xlfn.SWITCH(tblTesting[[#This Row],[Test ID]],"T020",_xlfn.XLOOKUP(tblTesting[[#This Row],[Test Key]],tblWeeklyMarkets[Test Key],tblWeeklyMarkets[Actual Miles],"NOT FOUND"),"T022",_xlfn.XLOOKUP(tblTesting[[#This Row],[Test Key]],tblWeeklyMarkets[Test Key],tblWeeklyMarkets[Travel Cost],"NOT FOUND"),"T030",_xlfn.XLOOKUP(tblTesting[[#This Row],[Test Key]],tblWeeklyMarkets[Test Key],tblWeeklyMarkets[Attendance Category],"NOT FOUND"),"T032",_xlfn.XLOOKUP(tblTesting[[#This Row],[Test Key]],tblWeeklyMarkets[Test Key],tblWeeklyMarkets[Attendance Category],"NOT FOUND"),"T050",_xlfn.XLOOKUP(tblTesting[[#This Row],[Test Key]],tblInventory[Test Key],tblInventory[Spoilage],"NOT FOUND"),"T052",_xlfn.XLOOKUP(tblTesting[[#This Row],[Test Key]],tblInventory[Test Key],tblInventory[Ending Inventory],"NOT FOUND"),"T060",_xlfn.XLOOKUP(tblTesting[[#This Row],[Test Key]],tblIngredientUsage[Test Key],tblIngredientUsage[Quantity Used],"NOT FOUND"),"T080",_xlfn.XLOOKUP(tblTesting[[#This Row],[Test Key]],tblProductMaster[Variation ID],tblProductMaster[Cost Complete],"NOT FOUND"),"T081",_xlfn.XLOOKUP(tblTesting[[#This Row],[Test Key]],tblProductMaster[Variation ID],tblProductMaster[Cost Complete],"NOT FOUND"),"T082",_xlfn.XLOOKUP(tblTesting[[#This Row],[Test Key]],tblProductCosts[Variation ID],tblProductCosts[Cost Review Status],"NOT FOUND"),"TEST NOT DEFINED") | G12: =IF(OR(tblTesting[[#This Row],[Actual Result]]="NOT FOUND",tblTesting[[#This Row],[Actual Result]]="TEST NOT DEFINED"),"FAIL",IF(AND(ISNUMBER(tblTesting[[#This Row],[Expected Result]]),ISNUMBER(tblTesting[[#This Row],[Actual Result]])),IF(ABS(tblTesting[[#This Row],[Expected Result]]-tblTesting[[#This Row],[Actual Result]])<0.01,"PASS","FAIL"),IF(tblTesting[[#This Row],[Expected Result]]=tblTesting[[#This Row],[Actual Result]],"PASS","FAIL"))) | H12: Missing cost
A13: T082 | B13: Product Cost | C13: TEST-VAR003 | E13: REVIEW COST | F13: =_xlfn.SWITCH(tblTesting[[#This Row],[Test ID]],"T020",_xlfn.XLOOKUP(tblTesting[[#This Row],[Test Key]],tblWeeklyMarkets[Test Key],tblWeeklyMarkets[Actual Miles],"NOT FOUND"),"T022",_xlfn.XLOOKUP(tblTesting[[#This Row],[Test Key]],tblWeeklyMarkets[Test Key],tblWeeklyMarkets[Travel Cost],"NOT FOUND"),"T030",_xlfn.XLOOKUP(tblTesting[[#This Row],[Test Key]],tblWeeklyMarkets[Test Key],tblWeeklyMarkets[Attendance Category],"NOT FOUND"),"T032",_xlfn.XLOOKUP(tblTesting[[#This Row],[Test Key]],tblWeeklyMarkets[Test Key],tblWeeklyMarkets[Attendance Category],"NOT FOUND"),"T050",_xlfn.XLOOKUP(tblTesting[[#This Row],[Test Key]],tblInventory[Test Key],tblInventory[Spoilage],"NOT FOUND"),"T052",_xlfn.XLOOKUP(tblTesting[[#This Row],[Test Key]],tblInventory[Test Key],tblInventory[Ending Inventory],"NOT FOUND"),"T060",_xlfn.XLOOKUP(tblTesting[[#This Row],[Test Key]],tblIngredientUsage[Test Key],tblIngredientUsage[Quantity Used],"NOT FOUND"),"T080",_xlfn.XLOOKUP(tblTesting[[#This Row],[Test Key]],tblProductMaster[Variation ID],tblProductMaster[Cost Complete],"NOT FOUND"),"T081",_xlfn.XLOOKUP(tblTesting[[#This Row],[Test Key]],tblProductMaster[Variation ID],tblProductMaster[Cost Complete],"NOT FOUND"),"T082",_xlfn.XLOOKUP(tblTesting[[#This Row],[Test Key]],tblProductCosts[Variation ID],tblProductCosts[Cost Review Status],"NOT FOUND"),"TEST NOT DEFINED") | G13: =IF(OR(tblTesting[[#This Row],[Actual Result]]="NOT FOUND",tblTesting[[#This Row],[Actual Result]]="TEST NOT DEFINED"),"FAIL",IF(AND(ISNUMBER(tblTesting[[#This Row],[Expected Result]]),ISNUMBER(tblTesting[[#This Row],[Actual Result]])),IF(ABS(tblTesting[[#This Row],[Expected Result]]-tblTesting[[#This Row],[Actual Result]])<0.01,"PASS","FAIL"),IF(tblTesting[[#This Row],[Expected Result]]=tblTesting[[#This Row],[Actual Result]],"PASS","FAIL"))) | H13: Old cost

Sheet Data_Dictionary
A1: DATA DICTIONARY
A3: Table | B3: Column | C3: Data Type | D3: Required | E3: Formula | F3: Description
A4: tblWeeklyMarkets | B4: Test Key | C4: Text | D4: No | E4: No | F4: Test fixture identifier
A5: tblWeeklyMarkets | B5: Market Date | C5: Date | D5: Yes | E5: No | F5: Actual attended/planned date
A6: tblWeeklyMarkets | B6: Market | C6: Text | D6: Yes | E6: No | F6: Market name
A7: tblWeeklyMarkets | B7: Market Status | C7: Text | D7: Yes | E7: No | F7: Single user-facing status
A8: tblWeeklyMarkets | B8: Market Day Score | C8: Text | D8: No | E8: No | F8: Excellent to Terrible
A9: tblWeeklyMarkets | B9: Notes | C9: Text | D9: No | E9: No | F9: Optional notes
A10: tblWeeklyMarkets | B10: Override Miles | C10: Number | D10: No | E10: No | F10: Optional exception
A11: tblWeeklyMarkets | B11: Attendance Category | C11: Text | D11: No | E11: Yes | F11: Derived
A12: tblWeeklyMarkets | B12: Market Match Count | C12: Number | D12: No | E12: Yes | F12: Effective-date matches
A13: tblWeeklyMarkets | B13: Market Fee | C13: Currency | D13: No | E13: Yes | F13: Date-effective default
A14: tblWeeklyMarkets | B14: Actual Miles | C14: Number | D14: No | E14: Yes | F14: Override or default
... A49: tblProductSetup | B49: Test Record | C49: Yes/No | D49: Yes | E49: No | F49: Test isolation

Sheet Settings
A1: SETTINGS
A3: Setting | B3: Value
A4: Mileage Rate | B4: 0.67
A5: Market Ranking Minimum Visits | B5: 5
A6: Week Starts On | B6: Monday
A7: Testing Mode | B7: No
A8: Weekly Profit Goal | B8: 300
A9: Safety Stock % | B9: 0.2

Sheet Market_Master
A1: MARKET MASTER
A3: Market | B3: Start Date | C3: End Date | D3: Market Fee | E3: Default Round Trip Miles | F3: Default Travel Minutes | G3: Active | H3: Invalid Date Range | I3: Fee Validation | J3: Conflict Details | K3: Overlap Count | L3: Test Record
A4: TEST-ORLANDO | B4: 46023 | D4: 40 | E4: 84 | F4: 90 | G4: =IF(OR(tblMarketMaster[[#This Row],[End Date]]="",tblMarketMaster[[#This Row],[End Date]]>=TODAY()),"Active","Expired") | H4: =IF(OR(tblMarketMaster[[#This Row],[Start Date]]="",tblMarketMaster[[#This Row],[End Date]]=""),"",IF(tblMarketMaster[[#This Row],[End Date]]<tblMarketMaster[[#This Row],[Start Date]],"INVALID","OK")) | I4: =IF(tblMarketMaster[[#This Row],[Market Fee]]="","MISSING FEE",IF(NOT(ISNUMBER(tblMarketMaster[[#This Row],[Market Fee]])),"INVALID FEE",IF(tblMarketMaster[[#This Row],[Market Fee]]<0,"INVALID FEE","OK"))) | J4: =_xlfn.LET(M,tblMarketMaster[[#This Row],[Market]],S,tblMarketMaster[[#This Row],[Start Date]],E,IF(tblMarketMaster[[#This Row],[End Date]]="",DATE(9999,12,31),tblMarketMaster[[#This Row],[End Date]]),OM,tblMarketMaster[Market],OS,tblMarketMaster[Start Date],OE,IF(tblMarketMaster[End Date]="",DATE(9999,12,31),tblMarketMaster[End Date]),OF,tblMarketMaster[Market Fee],Matches,(OM=M)*(OS<=E)*(OE>=S)*(ROW(OM)<>ROW()),IFERROR(_xlfn.TEXTJOIN(CHAR(10),TRUE,_xlfn._xlws.FILTER(OM&" | $"&TEXT(OF,"0.00")&" | "&TEXT(OS,"m/d/yyyy")&" to "&IF(OE=DATE(9999,12,31),"Current",TEXT(OE,"m/d/yyyy")),Matches)),"")) | K4: =IF(tblMarketMaster[[#This Row],[Conflict Details]]="",0,LEN(tblMarketMaster[[#This Row],[Conflict Details]])-LEN(SUBSTITUTE(tblMarketMaster[[#This Row],[Conflict Details]],CHAR(10),""))+1) | L4: Yes
A5: TEST-HAINES | B5: 46023 | D5: 25 | E5: 18 | F5: 25 | G5: =IF(OR(tblMarketMaster[[#This Row],[End Date]]="",tblMarketMaster[[#This Row],[End Date]]>=TODAY()),"Active","Expired") | H5: =IF(OR(tblMarketMaster[[#This Row],[Start Date]]="",tblMarketMaster[[#This Row],[End Date]]=""),"",IF(tblMarketMaster[[#This Row],[End Date]]<tblMarketMaster[[#This Row],[Start Date]],"INVALID","OK")) | I5: =IF(tblMarketMaster[[#This Row],[Market Fee]]="","MISSING FEE",IF(NOT(ISNUMBER(tblMarketMaster[[#This Row],[Market Fee]])),"INVALID FEE",IF(tblMarketMaster[[#This Row],[Market Fee]]<0,"INVALID FEE","OK"))) | J5: =_xlfn.LET(M,tblMarketMaster[[#This Row],[Market]],S,tblMarketMaster[[#This Row],[Start Date]],E,IF(tblMarketMaster[[#This Row],[End Date]]="",DATE(9999,12,31),tblMarketMaster[[#This Row],[End Date]]),OM,tblMarketMaster[Market],OS,tblMarketMaster[Start Date],OE,IF(tblMarketMaster[End Date]="",DATE(9999,12,31),tblMarketMaster[End Date]),OF,tblMarketMaster[Market Fee],Matches,(OM=M)*(OS<=E)*(OE>=S)*(ROW(OM)<>ROW()),IFERROR(_xlfn.TEXTJOIN(CHAR(10),TRUE,_xlfn._xlws.FILTER(OM&" | $"&TEXT(OF,"0.00")&" | "&TEXT(OS,"m/d/yyyy")&" to "&IF(OE=DATE(9999,12,31),"Current",TEXT(OE,"m/d/yyyy")),Matches)),"")) | K5: =IF(tblMarketMaster[[#This Row],[Conflict Details]]="",0,LEN(tblMarketMaster[[#This Row],[Conflict Details]])-LEN(SUBSTITUTE(tblMarketMaster[[#This Row],[Conflict Details]],CHAR(10),""))+1) | L5: Yes

Sheet Product_Setup_Data
A1: PRODUCT SETUP DATA
A3: Variation ID | B3: Shelf Stable | C3: Spoils If Unsold | D3: Product Group | E3: Product Active | F3: Notes | G3: Test Record
A4: TEST-VAR001 | B4: Yes | C4: Yes | D4: Jam | E4: Yes | F4: Fixture | G4: Yes
A5: TEST-VAR002 | B5: Yes | C5: No | D5: Jam | E5: Yes | F5: Fixture | G5: Yes
A6: TEST-VAR003 | B6: No | C6: Yes | D6: Fresh | E6: Yes | F6: Fixture | G6: Yes
A7: TEST-VAR004 | B7: Yes | C7: Yes | D7: Honey | E7: Yes | F7: Fixture | G7: Yes

Sheet Recipe_Master
A1: RECIPE MASTER
A3: Recipe ID | B3: Recipe Name | C3: Recipe Active | D3: Notes | E3: Test Record
A4: TEST-R001 | B4: Test Strawberry Jam Base | C4: Yes | D4: Fixture | E4: Yes
A5: TEST-R002 | B5: Test Bread Base | C5: Yes | D5: Fixture | E5: Yes

Sheet Product_Recipe_Map
A1: PRODUCT RECIPE MAPPING
A3: Variation ID | B3: Recipe ID | C3: Test Record
A4: TEST-VAR001 | B4: TEST-R001 | C4: Yes
A5: TEST-VAR002 | B5: TEST-R001 | C5: Yes
A6: TEST-VAR003 | B6: TEST-R002 | C6: Yes

Sheet Recipe_Ingredients
A1: RECIPE INGREDIENTS
A3: Recipe ID | B3: Ingredient | C3: Quantity Per Item | D3: Unit | E3: Test Record
A4: TEST-R001 | B4: Strawberries | C4: 0.4 | D4: lb | E4: Yes
A5: TEST-R001 | B5: Sugar | C5: 0.2 | D5: lb | E5: Yes
A6: TEST-R001 | B6: Jar | C6: 1 | D6: each | E6: Yes
A7: TEST-R002 | B7: Flour | C7: 0.5 | D7: lb | E7: Yes

Sheet Product_Costs
A1: PRODUCT COSTS
A3: Variation ID | B3: Effective Date | C3: Manual Cost | D3: Cost Review Status | E3: Test Record
A4: TEST-VAR001 | B4: 46023 | C4: 2.15 | D4: OK | E4: Yes
A5: TEST-VAR003 | B5: 45658 | C5: 1.5 | D5: REVIEW COST | E5: Yes

Sheet Ingredient_Cost_History
A1: INGREDIENT COST HISTORY
A3: Ingredient | B3: Effective Date | C3: Cost Per Unit | D3: Unit | E3: Test Record
A4: Sugar | B4: 45658 | C4: 0.75 | D4: lb | E4: Yes
A5: Sugar | B5: 46023 | C5: 0.82 | D5: lb | E5: Yes
A6: Strawberries | B6: 46023 | C6: 2 | D6: lb | E6: Yes

Sheet Business_Exceptions
A1: BUSINESS EXCEPTIONS
A3: Start Date | B3: End Date | C3: Exception Type | D3: Applies To | E3: Market | F3: Notes | G3: Business Impact | H3: Date Validation | I3: Test Record
A4: 46034 | B4: 46040 | C4: Vacation | D4: Entire Business | F4: Fixture | G4: No Sales Expected | H4: =IF(tblBusinessExceptions[[#This Row],[End Date]]<tblBusinessExceptions[[#This Row],[Start Date]],"INVALID","OK") | I4: Yes

Sheet Inventory
A1: INVENTORY
A3: Test Key | B3: Variation ID | C3: Inventory Date | D3: Beginning Inventory | E3: Produced | F3: Sold | G3: Samples | H3: Available | I3: Inventory Variance | J3: Spoilage | K3: Ending Inventory | L3: Validation | M3: Test Record
A4: TEST-INV-SPOIL | B4: TEST-VAR001 | C4: 46027 | D4: 0 | E4: 20 | F4: 15 | G4: 2 | H4: =tblInventory[[#This Row],[Beginning Inventory]]+tblInventory[[#This Row],[Produced]] | I4: =tblInventory[[#This Row],[Available]]-tblInventory[[#This Row],[Sold]]-tblInventory[[#This Row],[Samples]] | J4: =IF(_xlfn.XLOOKUP(tblInventory[[#This Row],[Variation ID]],tblProductSetup[Variation ID],tblProductSetup[Spoils If Unsold],"Yes")="Yes",MAX(0,tblInventory[[#This Row],[Inventory Variance]]),0) | K4: =IF(_xlfn.XLOOKUP(tblInventory[[#This Row],[Variation ID]],tblProductSetup[Variation ID],tblProductSetup[Spoils If Unsold],"Yes")="Yes",0,MAX(0,tblInventory[[#This Row],[Inventory Variance]]-tblInventory[[#This Row],[Spoilage]])) | L4: =IF(tblInventory[[#This Row],[Inventory Variance]]<0,"ERROR: SOLD/SAMPLES EXCEED AVAILABLE","OK") | M4: Yes
A5: TEST-INV-CARRY | B5: TEST-VAR002 | C5: 46027 | D5: 0 | E5: 20 | F5: 15 | G5: 2 | H5: =tblInventory[[#This Row],[Beginning Inventory]]+tblInventory[[#This Row],[Produced]] | I5: =tblInventory[[#This Row],[Available]]-tblInventory[[#This Row],[Sold]]-tblInventory[[#This Row],[Samples]] | J5: =IF(_xlfn.XLOOKUP(tblInventory[[#This Row],[Variation ID]],tblProductSetup[Variation ID],tblProductSetup[Spoils If Unsold],"Yes")="Yes",MAX(0,tblInventory[[#This Row],[Inventory Variance]]),0) | K5: =IF(_xlfn.XLOOKUP(tblInventory[[#This Row],[Variation ID]],tblProductSetup[Variation ID],tblProductSetup[Spoils If Unsold],"Yes")="Yes",0,MAX(0,tblInventory[[#This Row],[Inventory Variance]]-tblInventory[[#This Row],[Spoilage]])) | L5: =IF(tblInventory[[#This Row],[Inventory Variance]]<0,"ERROR: SOLD/SAMPLES EXCEED AVAILABLE","OK") | M5: Yes

Sheet Ingredient_Purchases

Sheet Expenses

Sheet Market_Rankings
A1: MARKET RANKINGS
A3: Market | B3: Visit Count | C3: Eligibility | D3: Lifetime Avg Profit | E3: Business Score | F3: Personal Score | G3: Business Rank | H3: Personal Rank | I3: Confidence | J3: Ranking Reason | K3: Test Record
A4: TEST-ORLANDO | B4: 5 | C4: =IF(tblMarketRankings[[#This Row],[Visit Count]]>=MarketRankingMinimumVisits,"Eligible","Not Ranked") | D4: 200 | E4: 85 | F4: 80 | G4: =IF(OR(tblMarketRankings[[#This Row],[Eligibility]]<>"Eligible",tblMarketRankings[[#This Row],[Test Record]]<>"No"),"N/R",1+SUMPRODUCT(--(tblMarketRankings[Eligibility]="Eligible"),--(tblMarketRankings[Test Record]="No"),--(((tblMarketRankings[Business Score]>tblMarketRankings[[#This Row],[Business Score]])+((tblMarketRankings[Business Score]=tblMarketRankings[[#This Row],[Business Score]])*(tblMarketRankings[Lifetime Avg Profit]>tblMarketRankings[[#This Row],[Lifetime Avg Profit]]))+((tblMarketRankings[Business Score]=tblMarketRankings[[#This Row],[Business Score]])*(tblMarketRankings[Lifetime Avg Profit]=tblMarketRankings[[#This Row],[Lifetime Avg Profit]])*(tblMarketRankings[Visit Count]>tblMarketRankings[[#This Row],[Visit Count]]))+((tblMarketRankings[Business Score]=tblMarketRankings[[#This Row],[Business Score]])*(tblMarketRankings[Lifetime Avg Profit]=tblMarketRankings[[#This Row],[Lifetime Avg Profit]])*(tblMarketRankings[Visit Count]=tblMarketRankings[[#This Row],[Visit Count]])*(tblMarketRankings[Market]<tblMarketRankings[[#This Row],[Market]])))>0))) | H4: =IF(OR(tblMarketRankings[[#This Row],[Eligibility]]<>"Eligible",tblMarketRankings[[#This Row],[Test Record]]<>"No"),"N/R",1+SUMPRODUCT(--(tblMarketRankings[Eligibility]="Eligible"),--(tblMarketRankings[Test Record]="No"),--(((tblMarketRankings[Personal Score]>tblMarketRankings[[#This Row],[Personal Score]])+((tblMarketRankings[Personal Score]=tblMarketRankings[[#This Row],[Personal Score]])*(tblMarketRankings[Lifetime Avg Profit]>tblMarketRankings[[#This Row],[Lifetime Avg Profit]]))+((tblMarketRankings[Personal Score]=tblMarketRankings[[#This Row],[Personal Score]])*(tblMarketRankings[Lifetime Avg Profit]=tblMarketRankings[[#This Row],[Lifetime Avg Profit]])*(tblMarketRankings[Visit Count]>tblMarketRankings[[#This Row],[Visit Count]]))+((tblMarketRankings[Personal Score]=tblMarketRankings[[#This Row],[Personal Score]])*(tblMarketRankings[Lifetime Avg Profit]=tblMarketRankings[[#This Row],[Lifetime Avg Profit]])*(tblMarketRankings[Visit Count]=tblMarketRankings[[#This Row],[Visit Count]])*(tblMarketRankings[Market]<tblMarketRankings[[#This Row],[Market]])))>0))) | I4: =IF(tblMarketRankings[[#This Row],[Visit Count]]<MarketRankingMinimumVisits,"Insufficient Data",IF(tblMarketRankings[[#This Row],[Visit Count]]<10,"Medium","High")) | J4: =IF(tblMarketRankings[[#This Row],[Test Record]]="Yes","Test Record",IF(tblMarketRankings[[#This Row],[Visit Count]]<MarketRankingMinimumVisits,"Needs "&(MarketRankingMinimumVisits-tblMarketRankings[[#This Row],[Visit Count]])&" More Visits","Eligible")) | K4: Yes
A5: TEST-HAINES | B5: 5 | C5: =IF(tblMarketRankings[[#This Row],[Visit Count]]>=MarketRankingMinimumVisits,"Eligible","Not Ranked") | D5: 200 | E5: 85 | F5: 80 | G5: =IF(OR(tblMarketRankings[[#This Row],[Eligibility]]<>"Eligible",tblMarketRankings[[#This Row],[Test Record]]<>"No"),"N/R",1+SUMPRODUCT(--(tblMarketRankings[Eligibility]="Eligible"),--(tblMarketRankings[Test Record]="No"),--(((tblMarketRankings[Business Score]>tblMarketRankings[[#This Row],[Business Score]])+((tblMarketRankings[Business Score]=tblMarketRankings[[#This Row],[Business Score]])*(tblMarketRankings[Lifetime Avg Profit]>tblMarketRankings[[#This Row],[Lifetime Avg Profit]]))+((tblMarketRankings[Business Score]=tblMarketRankings[[#This Row],[Business Score]])*(tblMarketRankings[Lifetime Avg Profit]=tblMarketRankings[[#This Row],[Lifetime Avg Profit]])*(tblMarketRankings[Visit Count]>tblMarketRankings[[#This Row],[Visit Count]]))+((tblMarketRankings[Business Score]=tblMarketRankings[[#This Row],[Business Score]])*(tblMarketRankings[Lifetime Avg Profit]=tblMarketRankings[[#This Row],[Lifetime Avg Profit]])*(tblMarketRankings[Visit Count]=tblMarketRankings[[#This Row],[Visit Count]])*(tblMarketRankings[Market]<tblMarketRankings[[#This Row],[Market]])))>0))) | H5: =IF(OR(tblMarketRankings[[#This Row],[Eligibility]]<>"Eligible",tblMarketRankings[[#This Row],[Test Record]]<>"No"),"N/R",1+SUMPRODUCT(--(tblMarketRankings[Eligibility]="Eligible"),--(tblMarketRankings[Test Record]="No"),--(((tblMarketRankings[Personal Score]>tblMarketRankings[[#This Row],[Personal Score]])+((tblMarketRankings[Personal Score]=tblMarketRankings[[#This Row],[Personal Score]])*(tblMarketRankings[Lifetime Avg Profit]>tblMarketRankings[[#This Row],[Lifetime Avg Profit]]))+((tblMarketRankings[Personal Score]=tblMarketRankings[[#This Row],[Personal Score]])*(tblMarketRankings[Lifetime Avg Profit]=tblMarketRankings[[#This Row],[Lifetime Avg Profit]])*(tblMarketRankings[Visit Count]>tblMarketRankings[[#This Row],[Visit Count]]))+((tblMarketRankings[Personal Score]=tblMarketRankings[[#This Row],[Personal Score]])*(tblMarketRankings[Lifetime Avg Profit]=tblMarketRankings[[#This Row],[Lifetime Avg Profit]])*(tblMarketRankings[Visit Count]=tblMarketRankings[[#This Row],[Visit Count]])*(tblMarketRankings[Market]<tblMarketRankings[[#This Row],[Market]])))>0))) | I5: =IF(tblMarketRankings[[#This Row],[Visit Count]]<MarketRankingMinimumVisits,"Insufficient Data",IF(tblMarketRankings[[#This Row],[Visit Count]]<10,"Medium","High")) | J5: =IF(tblMarketRankings[[#This Row],[Test Record]]="Yes","Test Record",IF(tblMarketRankings[[#This Row],[Visit Count]]<MarketRankingMinimumVisits,"Needs "&(MarketRankingMinimumVisits-tblMarketRankings[[#This Row],[Visit Count]])&" More Visits","Eligible")) | K5: Yes

Sheet Product_Rankings
A1: PRODUCT RANKINGS
A3: Variation ID | B3: Product Name | C3: Annual Profit | D3: Profit Rank | E3: Test Record
A4: TEST-VAR001 | B4: Test Strawberry Jam 8 oz | C4: 500 | D4: 1 | E4: Yes

Sheet Error_Log
A1: ERROR LOG
A3: Date Found | B3: Error Type | C3: Source | D3: Reference | E3: Description | F3: Severity | G3: Status | H3: Resolution Notes
A4: 46027 | B4: Fixture | C4: TESTING | D4: TEST-001 | E4: Test error-log fixture | F4: Low | G4: Resolved | H4: Fixture only

Sheet Workbook_Version
A1: WORKBOOK VERSION
A3: Version | B3: Date | C3: Change | D3: Tested | E3: Approved By
A4: 1.0 | B4: 46290 | C4: Initial governed template | D4: Yes

Sheet Square_Catalog
A1: SQUARE CATALOG (QUERY OUTPUT)
A3: Variation ID | B3: Item ID | C3: Product Name | D3: Variation Name | E3: SKU | F3: First Seen Date | G3: Last Seen Date | H3: Active In Square | I3: Test Record
A4: TEST-VAR001 | B4: TEST-ITEM1 | C4: Test Strawberry Jam | D4: 8 oz | E4: T-SJ8 | F4: 45809 | G4: 46027 | H4: Yes | I4: Yes
A5: TEST-VAR002 | B5: TEST-ITEM1 | C5: Test Strawberry Jam | D5: 16 oz | E5: T-SJ16 | F5: 45809 | G5: 46027 | H5: Yes | I5: Yes
A6: TEST-VAR003 | B6: TEST-ITEM2 | C6: Test Fresh Bread | D6: Regular | E6: T-BRD | F6: 45839 | G6: 46027 | H6: Yes | I6: Yes
A7: TEST-VAR004 | B7: TEST-ITEM3 | C7: Test Hot Honey | D7: Regular | E7: T-HNY | F7: 45870 | G7: 46027 | H7: Yes | I7: Yes

Sheet Sales_Data
A1: SALES DATA (QUERY OUTPUT)
A3: Sale Timestamp | B3: Variation ID | C3: Product Name | D3: Quantity Sold | E3: Gross Sales | F3: Effective Product Cost | G3: COGS | H3: Square Fee | I3: Source File | J3: Duplicate Key | K3: Test Record
A4: 46027.417 | B4: TEST-VAR001 | C4: Test Strawberry Jam 8 oz | D4: 15 | E4: 150 | F4: 2.15 | G4: =tblSalesData[[#This Row],[Quantity Sold]]*tblSalesData[[#This Row],[Effective Product Cost]] | H4: 4.5 | I4: test_week1.csv | J4: TX1-L1 | K4: Yes

Sheet Import_Log
A1: IMPORT LOG
A3: Import Timestamp | B3: Source File | C3: Imported By | D3: Records Imported | E3: Status | F3: Test Record
A4: 46028.333 | B4: test_week1.csv | C4: Test User | D4: 1 | E4: Success | F4: Yes

Sheet Ingredient_Usage
A1: INGREDIENT USAGE
A3: Test Key | B3: Usage Date | C3: Recipe ID | D3: Variation ID | E3: Ingredient | F3: Quantity Produced | G3: Quantity Per Item | H3: Quantity Used | I3: Unit Cost | J3: Usage Cost | K3: Test Record
A4: TEST-USAGE-1 | B4: 46027 | C4: TEST-R001 | D4: TEST-VAR001 | E4: Strawberries | F4: 20 | G4: 0.4 | H4: =tblIngredientUsage[[#This Row],[Quantity Produced]]*tblIngredientUsage[[#This Row],[Quantity Per Item]] | I4: =_xlfn.LET(Ing,tblIngredientUsage[[#This Row],[Ingredient]],Dt,tblIngredientUsage[[#This Row],[Usage Date]],EffDate,IFERROR(_xlfn.MAXIFS(tblIngredientCostHistory[Effective Date],tblIngredientCostHistory[Ingredient],Ing,tblIngredientCostHistory[Effective Date],"<="&Dt),0),IF(EffDate=0,"",_xlfn.XLOOKUP(1,(tblIngredientCostHistory[Ingredient]=Ing)*(tblIngredientCostHistory[Effective Date]=EffDate),tblIngredientCostHistory[Cost Per Unit],""))) | J4: =IFERROR(tblIngredientUsage[[#This Row],[Quantity Used]]*tblIngredientUsage[[#This Row],[Unit Cost]],0) | K4: Yes

Sheet Executive_Dashboard
A1: EXECUTIVE DASHBOARD
A3: Weekly | D3: Monthly | G3: Year to Date
A4: Weekly Revenue | B4: =SUMIFS(tblSalesData[Gross Sales],tblSalesData[Sale Timestamp],">="&CurrentWeekStart,tblSalesData[Sale Timestamp],"<"&CurrentWeekEnd+1,tblSalesData[Test Record],"No") | D4: Monthly Revenue | E4: =SUMIFS(tblSalesData[Gross Sales],tblSalesData[Sale Timestamp],">="&CurrentMonthStart,tblSalesData[Sale Timestamp],"<"&EOMONTH(TODAY(),0)+1,tblSalesData[Test Record],"No") | G4: YTD Revenue | H4: =SUMIFS(tblSalesData[Gross Sales],tblSalesData[Sale Timestamp],">="&CurrentYearStart,tblSalesData[Sale Timestamp],"<"&TODAY()+1,tblSalesData[Test Record],"No")
A5: Weekly Profit | B5: =B4-B5-B6-B7-B8-B9 | D5: Monthly COGS | E5: =SUMIFS(tblSalesData[COGS],tblSalesData[Sale Timestamp],">="&CurrentMonthStart,tblSalesData[Sale Timestamp],"<"&EOMONTH(TODAY(),0)+1,tblSalesData[Test Record],"No") | G5: YTD COGS | H5: =SUMIFS(tblSalesData[COGS],tblSalesData[Sale Timestamp],">="&CurrentYearStart,tblSalesData[Sale Timestamp],"<"&TODAY()+1,tblSalesData[Test Record],"No")
A6: Weekly COGS | B6: =SUMIFS(tblSalesData[COGS],tblSalesData[Sale Timestamp],">="&CurrentWeekStart,tblSalesData[Sale Timestamp],"<"&CurrentWeekEnd+1,tblSalesData[Test Record],"No") | D6: Monthly Market Fees | E6: =SUMIFS(tblWeeklyMarkets[Market Fee],tblWeeklyMarkets[Market Date],">="&CurrentMonthStart,tblWeeklyMarkets[Market Date],"<"&EOMONTH(TODAY(),0)+1,tblWeeklyMarkets[Test Record],"No") | G6: YTD Market Fees | H6: =SUMIFS(tblWeeklyMarkets[Market Fee],tblWeeklyMarkets[Market Date],">="&CurrentYearStart,tblWeeklyMarkets[Market Date],"<"&TODAY()+1,tblWeeklyMarkets[Test Record],"No")
A7: Weekly Market Fees | B7: =SUMIFS(tblWeeklyMarkets[Market Fee],tblWeeklyMarkets[Market Date],">="&CurrentWeekStart,tblWeeklyMarkets[Market Date],"<="&CurrentWeekEnd,tblWeeklyMarkets[Attendance Category],"Attended",tblWeeklyMarkets[Test Record],"No") | D7: Monthly Travel | E7: =SUMIFS(tblWeeklyMarkets[Travel Cost],tblWeeklyMarkets[Market Date],">="&CurrentMonthStart,tblWeeklyMarkets[Market Date],"<"&EOMONTH(TODAY(),0)+1,tblWeeklyMarkets[Test Record],"No") | G7: YTD Travel | H7: =SUMIFS(tblWeeklyMarkets[Travel Cost],tblWeeklyMarkets[Market Date],">="&CurrentYearStart,tblWeeklyMarkets[Market Date],"<"&TODAY()+1,tblWeeklyMarkets[Test Record],"No")
A8: Weekly Travel | B8: =SUMIFS(tblWeeklyMarkets[Travel Cost],tblWeeklyMarkets[Market Date],">="&CurrentWeekStart,tblWeeklyMarkets[Market Date],"<="&CurrentWeekEnd,tblWeeklyMarkets[Test Record],"No") | D8: Monthly Square Fees | E8: =SUMIFS(tblSalesData[Square Fee],tblSalesData[Sale Timestamp],">="&CurrentMonthStart,tblSalesData[Sale Timestamp],"<"&EOMONTH(TODAY(),0)+1,tblSalesData[Test Record],"No") | G8: YTD Square Fees | H8: =SUMIFS(tblSalesData[Square Fee],tblSalesData[Sale Timestamp],">="&CurrentYearStart,tblSalesData[Sale Timestamp],"<"&TODAY()+1,tblSalesData[Test Record],"No")
A9: Weekly Square Fees | B9: =SUMIFS(tblSalesData[Square Fee],tblSalesData[Sale Timestamp],">="&CurrentWeekStart,tblSalesData[Sale Timestamp],"<"&CurrentWeekEnd+1,tblSalesData[Test Record],"No") | D9: Monthly Expenses | E9: =SUMIFS(tblExpenses[Amount],tblExpenses[Date],">="&CurrentMonthStart,tblExpenses[Date],"<"&EOMONTH(TODAY(),0)+1,tblExpenses[Test Record],"No") | G9: YTD Expenses | H9: =SUMIFS(tblExpenses[Amount],tblExpenses[Date],">="&CurrentYearStart,tblExpenses[Date],"<"&TODAY()+1,tblExpenses[Test Record],"No")
A10: Weekly Other Expenses | B10: =SUMIFS(tblExpenses[Amount],tblExpenses[Date],">="&CurrentWeekStart,tblExpenses[Date],"<="&CurrentWeekEnd,tblExpenses[Test Record],"No") | D10: Monthly Profit | E10: =E4-E5-E6-E7-E8-E9 | G10: YTD Profit | H10: =H4-H5-H6-H7-H8-H9

Sheet Data_Quality
A1: DATA QUALITY DASHBOARD
A3: Quality Area | B3: Open Issues | C3: Weight | D3: Weighted Deduction | E3: Status | F3: Test Record
A4: Imports | B4: 0 | C4: 0.3 | D4: =MIN(100,tblDataQuality[[#This Row],[Open Issues]]*25)*tblDataQuality[[#This Row],[Weight]] | E4: =IF(tblDataQuality[[#This Row],[Open Issues]]=0,"PASS","REVIEW") | F4: No
A5: Product Setup | B5: 0 | C5: 0.3 | D5: =MIN(100,tblDataQuality[[#This Row],[Open Issues]]*25)*tblDataQuality[[#This Row],[Weight]] | E5: =IF(tblDataQuality[[#This Row],[Open Issues]]=0,"PASS","REVIEW") | F5: No
A6: Inventory | B6: 0 | C6: 0.2 | D6: =MIN(100,tblDataQuality[[#This Row],[Open Issues]]*25)*tblDataQuality[[#This Row],[Weight]] | E6: =IF(tblDataQuality[[#This Row],[Open Issues]]=0,"PASS","REVIEW") | F6: No
A7: Testing | B7: 0 | C7: 0.2 | D7: =MIN(100,tblDataQuality[[#This Row],[Open Issues]]*25)*tblDataQuality[[#This Row],[Weight]] | E7: =IF(tblDataQuality[[#This Row],[Open Issues]]=0,"PASS","REVIEW") | F7: No
A10: Health Score | B10: =MAX(0,100-SUM(tblDataQuality[Weighted Deduction]))
A11: Health Status | B11: =IF(B10>=95,"Excellent",IF(B10>=85,"Good",IF(B10>=70,"Needs Review","Action Required")))

Sheet Forecasting
A1: FORECASTING
A3: Metric | B3: Current Value | C3: 4 Week Avg | D3: 8 Week Avg | E3: 13 Week Avg | F3: Next Week Forecast | G3: Next Month Forecast | H3: Confidence | I3: Test Record
A4: Revenue | B4: 1000 | C4: 950 | D4: 900 | E4: 875 | F4: =ROUND(tblForecasting[[#This Row],[4 Week Avg]]*0.5+tblForecasting[[#This Row],[8 Week Avg]]*0.3+tblForecasting[[#This Row],[13 Week Avg]]*0.2,2) | G4: =tblForecasting[[#This Row],[Next Week Forecast]]*4.345 | H4: =IF(ABS(tblForecasting[[#This Row],[4 Week Avg]]-tblForecasting[[#This Row],[13 Week Avg]])/MAX(1,tblForecasting[[#This Row],[13 Week Avg]])<=0.10,"High",IF(ABS(tblForecasting[[#This Row],[4 Week Avg]]-tblForecasting[[#This Row],[13 Week Avg]])/MAX(1,tblForecasting[[#This Row],[13 Week Avg]])<=0.25,"Medium","Low")) | I4: Yes
A5: Profit | B5: 250 | C5: 230 | D5: 215 | E5: 200 | F5: =ROUND(tblForecasting[[#This Row],[4 Week Avg]]*0.5+tblForecasting[[#This Row],[8 Week Avg]]*0.3+tblForecasting[[#This Row],[13 Week Avg]]*0.2,2) | G5: =tblForecasting[[#This Row],[Next Week Forecast]]*4.345 | H5: =IF(ABS(tblForecasting[[#This Row],[4 Week Avg]]-tblForecasting[[#This Row],[13 Week Avg]])/MAX(1,tblForecasting[[#This Row],[13 Week Avg]])<=0.10,"High",IF(ABS(tblForecasting[[#This Row],[4 Week Avg]]-tblForecasting[[#This Row],[13 Week Avg]])/MAX(1,tblForecasting[[#This Row],[13 Week Avg]])<=0.25,"Medium","Low")) | I5: Yes

Sheet Product_Scorecards
A1: PRODUCT SCORECARDS
A3: Variation ID | B3: Product Name | C3: Revenue | D3: COGS | E3: Profit | F3: Margin % | G3: Units Sold | H3: Waste Units | I3: Waste % | J3: Growth % | K3: Lifecycle Status | L3: Test Record
